<?xml version="1.0" ?>
<robot name="p_jfernandes" xmlns:xacro="http://ros.org/wiki/xacro">
    <xacro:include filename="$(find turtlebot3_description)/urdf/common_properties.xacro"/>
    <xacro:include filename="$(find red_turtlebot3)/urdf/red_turtlebot3.gazebo.xacro"/>
    <xacro:property name="top_length" value="0.03"/>

    <xacro:property name="robot_name" value="red/"/>


    <link name="${robot_name}base_footprint"/>

    <joint name="base_joint" type="fixed">
        <parent link="${robot_name}base_footprint"/>
        <child link="${robot_name}base_link"/>
        <origin xyz="0 0 0.010" rpy="0 0 0"/>
    </joint>

    <link name="${robot_name}base_link">
        <visual>
            <origin xyz="-0.064 0 0.0" rpy="0 0 0"/>
            <geometry>
                <mesh filename="package://turtlebot3_description/meshes/bases/waffle_pi_base.stl"
                      scale="0.001 0.001 0.001"/>
            </geometry>
            <material name="light_black"/>
        </visual>

        <collision>
            <origin xyz="-0.064 0 0.047" rpy="0 0 0"/>
            <geometry>
                <box size="0.266 0.266 0.094"/>
            </geometry>
        </collision>

        <inertial>
            <origin xyz="0 0 0" rpy="0 0 0"/>
            <mass value="1.3729096e+00"/>
            <inertia ixx="8.7002718e-03" ixy="-4.7576583e-05" ixz="1.1160499e-04"
                     iyy="8.6195418e-03" iyz="-3.5422299e-06"
                     izz="1.4612727e-02"/>
        </inertial>
    </link>

    <!--    &lt;!&ndash;    add blue element   ********************** &ndash;&gt;-->
    <!--    <link name="${robot_name}stem">-->
    <!--        <visual>-->
    <!--            <origin xyz="0 0 0.0" rpy="0 0 0"/>-->
    <!--            <geometry>-->
    <!--                <cylinder length="0.1" radius="0.005"/>-->
    <!--            </geometry>-->
    <!--            <material name="dark"/>-->
    <!--        </visual>-->

    <!--        <collision>-->
    <!--            <origin xyz="0 0 0" rpy="0 0 0"/>-->
    <!--            <geometry>-->
    <!--                <cylinder length="0.1" radius="0.005"/>-->
    <!--            </geometry>-->
    <!--        </collision>-->
    <!--    </link>-->

    <!--    <joint name="stem_joint" type="fixed">-->
    <!--        <parent link="${robot_name}base_link"/>-->
    <!--        <child link="${robot_name}stem"/>-->
    <!--        <origin xyz="-0.16 0.07 0.14" rpy="0 0 0"/>-->
    <!--    </joint>-->

    <!--    <link name="${robot_name}top">-->
    <!--        <visual>-->
    <!--            <origin xyz="0 0 0.0" rpy="0 0 0"/>-->
    <!--            <geometry>-->
    <!--                <cylinder length="0.05" radius="0.05"/>-->
    <!--            </geometry>-->
    <!--            <material name="dark"/>-->
    <!--        </visual>-->

    <!--        <collision>-->
    <!--            <origin xyz="0 0 0" rpy="0 0 0"/>-->
    <!--            <geometry>-->
    <!--                <cylinder length="${top_length}" radius="0.04"/>-->
    <!--            </geometry>-->
    <!--        </collision>-->
    <!--    </link>-->

    <!--    <joint name="top_joint" type="fixed">-->
    <!--        <parent link="${robot_name}base_link"/>-->
    <!--        <child link="${robot_name}top"/>-->
    <!--        <origin xyz="-0.16 0.07 0.19" rpy="0 0 0"/>-->
    <!--    </joint>-->

    <!--    &lt;!&ndash;    ************************************************&ndash;&gt;-->

    <joint name="wheel_left_joint" type="continuous">
        <parent link="${robot_name}base_link"/>
        <child link="${robot_name}wheel_left_link"/>
        <origin xyz="0.0 0.144 0.023" rpy="-1.57 0 0"/>
        <axis xyz="0 0 1"/>
    </joint>

    <link name="${robot_name}wheel_left_link">
        <visual>
            <origin xyz="0 0 0" rpy="1.57 0 0"/>
            <geometry>
                <mesh filename="package://turtlebot3_description/meshes/wheels/left_tire.stl"
                      scale="0.001 0.001 0.001"/>
            </geometry>
            <material name="dark"/>
        </visual>

        <collision>
            <origin xyz="0 0 0" rpy="0 0 0"/>
            <geometry>
                <cylinder length="0.018" radius="0.033"/>
            </geometry>
        </collision>

        <inertial>
            <origin xyz="0 0 0"/>
            <mass value="2.8498940e-02"/>
            <inertia ixx="1.1175580e-05" ixy="-4.2369783e-11" ixz="-5.9381719e-09"
                     iyy="1.1192413e-05" iyz="-1.4400107e-11"
                     izz="2.0712558e-05"/>
        </inertial>
    </link>

    <joint name="wheel_right_joint" type="continuous">
        <parent link="${robot_name}base_link"/>
        <child link="${robot_name}wheel_right_link"/>
        <origin xyz="0.0 -0.144 0.023" rpy="-1.57 0 0"/>
        <axis xyz="0 0 1"/>
    </joint>

    <link name="${robot_name}wheel_right_link">
        <visual>
            <origin xyz="0 0 0" rpy="1.57 0 0"/>
            <geometry>
                <mesh filename="package://turtlebot3_description/meshes/wheels/right_tire.stl"
                      scale="0.001 0.001 0.001"/>
            </geometry>
            <material name="dark"/>
        </visual>

        <collision>
            <origin xyz="0 0 0" rpy="0 0 0"/>
            <geometry>
                <cylinder length="0.018" radius="0.033"/>
            </geometry>
        </collision>

        <inertial>
            <origin xyz="0 0 0"/>
            <mass value="2.8498940e-02"/>
            <inertia ixx="1.1175580e-05" ixy="-4.2369783e-11" ixz="-5.9381719e-09"
                     iyy="1.1192413e-05" iyz="-1.4400107e-11"
                     izz="2.0712558e-05"/>
        </inertial>
    </link>

    <joint name="caster_back_right_joint" type="fixed">
        <parent link="${robot_name}base_link"/>
        <child link="${robot_name}caster_back_right_link"/>
        <origin xyz="-0.177 -0.064 -0.004" rpy="-1.57 0 0"/>
    </joint>

    <link name="${robot_name}caster_back_right_link">
        <collision>
            <origin xyz="0 0.001 0" rpy="0 0 0"/>
            <geometry>
                <box size="0.030 0.009 0.020"/>
            </geometry>
        </collision>

        <inertial>
            <origin xyz="0 0 0"/>
            <mass value="0.005"/>
            <inertia ixx="0.001" ixy="0.0" ixz="0.0"
                     iyy="0.001" iyz="0.0"
                     izz="0.001"/>
        </inertial>
    </link>

    <joint name="caster_back_left_joint" type="fixed">
        <parent link="${robot_name}base_link"/>
        <child link="${robot_name}caster_back_left_link"/>
        <origin xyz="-0.177 0.064 -0.004" rpy="-1.57 0 0"/>
    </joint>

    <link name="${robot_name}caster_back_left_link">
        <collision>
            <origin xyz="0 0.001 0" rpy="0 0 0"/>
            <geometry>
                <box size="0.030 0.009 0.020"/>
            </geometry>
        </collision>

        <inertial>
            <origin xyz="0 0 0"/>
            <mass value="0.005"/>
            <inertia ixx="0.001" ixy="0.0" ixz="0.0"
                     iyy="0.001" iyz="0.0"
                     izz="0.001"/>
        </inertial>
    </link>

    <joint name="imu_joint" type="fixed">
        <parent link="${robot_name}base_link"/>
        <child link="${robot_name}imu_link"/>
        <origin xyz="0.0 0 0.068" rpy="0 0 0"/>
    </joint>

    <link name="${robot_name}imu_link"/>

    <joint name="scan_joint" type="fixed">
        <parent link="${robot_name}base_link"/>
        <child link="${robot_name}base_scan"/>
        <origin xyz="-0.064 0 0.122" rpy="0 0 0"/>
    </joint>

    <link name="${robot_name}base_scan">
        <visual>
            <origin xyz="0 0 0.0" rpy="0 0 0"/>
            <geometry>
                <mesh filename="package://turtlebot3_description/meshes/sensors/lds.stl" scale="0.001 0.001 0.001"/>
            </geometry>
            <material name="dark"/>
        </visual>

        <collision>
            <origin xyz="0.015 0 -0.0065" rpy="0 0 0"/>
            <geometry>
                <cylinder length="0.0315" radius="0.055"/>
            </geometry>
        </collision>

        <inertial>
            <mass value="0.114"/>
            <origin xyz="0 0 0"/>
            <inertia ixx="0.001" ixy="0.0" ixz="0.0"
                     iyy="0.001" iyz="0.0"
                     izz="0.001"/>
        </inertial>
    </link>

    <joint name="camera_joint" type="fixed">
        <origin xyz="0.073 -0.011 0.084" rpy="0 0 0"/>
        <parent link="${robot_name}base_link"/>
        <child link="${robot_name}camera_link"/>
    </joint>

    <link name="${robot_name}camera_link">
        <collision>
            <origin xyz="0.005 0.011 0.013" rpy="0 0 0"/>
            <geometry>
                <box size="0.015 0.030 0.027"/>
            </geometry>
        </collision>
    </link>

    <joint name="camera_rgb_joint" type="fixed">
        <origin xyz="0.003 0.011 0.009" rpy="0 0 0"/>
        <parent link="${robot_name}camera_link"/>
        <child link="${robot_name}camera_rgb_frame"/>
    </joint>

    <link name="${robot_name}camera_rgb_frame"/>

    <joint name="camera_rgb_optical_joint" type="fixed">
        <origin xyz="0 0 0" rpy="-1.57 0 -1.57"/>
        <parent link="${robot_name}camera_rgb_frame"/>
        <child link="${robot_name}camera_rgb_optical_frame"/>
    </joint>

    <link name="${robot_name}camera_rgb_optical_frame"/>

</robot>
